Exception in thread Thread-1:
Traceback (most recent call last):
  File "/usr/lib/python3.8/threading.py", line 932, in _bootstrap_inner
    self.run()
  File "/usr/lib/python3.8/threading.py", line 870, in run
    self._target(*self._args, **self._kwargs)
  File "/home/ubuntu/stock-hit/cncr.py", line 70, in thread_one
    schedule.run_pending()
  File "/home/ubuntu/stock-hit/venv/lib/python3.8/site-packages/schedule/__init__.py", line 780, in run_pending
    default_scheduler.run_pending()
  File "/home/ubuntu/stock-hit/venv/lib/python3.8/site-packages/schedule/__init__.py", line 100, in run_pending
    self._run_job(job)
  File "/home/ubuntu/stock-hit/venv/lib/python3.8/site-packages/schedule/__init__.py", line 172, in _run_job
    ret = job.run()
  File "/home/ubuntu/stock-hit/venv/lib/python3.8/site-packages/schedule/__init__.py", line 661, in run
    ret = self.job_func()
  File "/home/ubuntu/stock-hit/cncr.py", line 36, in notify
    current_price = ticker.history(period='1d')['Close'][0]
  File "/home/ubuntu/stock-hit/venv/lib/python3.8/site-packages/pandas/core/series.py", line 979, in __getitem__
    return self._values[key]
IndexError: index 0 is out of bounds for axis 0 with size 0
Exiting immediately!
